Workbook

Sheet Benchmark Bogotá
A1: BENCHMARK
A3: 1. ECONOMÍA POR SERVICIO
A4: Servicio | B4: Precio min (COP) | C4: Precio típico (COP) | D4: Precio max (COP) | E4: COGS insumo estimado | F4: Margen bruto estimado | G4: Recurrencia (frecuencia) | H4: Tipo de demanda
A5: Toxina botulínica (botox) | B5: 400000 | C5: 1100000 | D5: 2000000 | E5: 15-25% | F5: 70-80% | G5: Alta · cada 4-5 meses | H5: Existente / marca fuerte
A6: Ácido hialurónico — volumen (labios, ojeras, armonización) | B6: 900000 | C6: 1400000 | D6: 3500000 | E6: 20-30% | F6: 65-75% | G6: Media · 8-18 meses | H6: Existente / marca fuerte
A7: Ácido hialurónico — hidratación (skinboosters, NCTF) | B7: 900000 | C7: 1200000 | D7: 2000000 | E7: 30-40% | F7: 55-70% | G7: Media-alta · protocolo 3 + mant. | H7: En crecimiento (prejuvenation)
A8: Microagujas (+ exosomas / NCTF) | B8: 555000 | C8: 750000 | D8: 1290000 | E8: 25-35% | F8: 65-75% | G8: Alta · serie 3-6 + mant. | H8: Media
A9: Peelings químicos | B9: 200000 | C9: 400000 | D9: 700000 | E9: 10-20% | F9: 78-85% | G9: Alta · serie + mant. | H9: Media-alta
A10: Bioestimuladores (Sculptra, Radiesse, Profhilo, Harmonyca) | B10: 1800000 | C10: 2600000 | D10: 5500000 | E10: 35-45% | F10: 55-65% | G10: Baja · protocolo, dura ~2 años | H10: En crecimiento / latente
A11: Enzimas recombinantes (corporal) | B11: 500000 | C11: 900000 | D11: 1800000 | E11: 35-45% | F11: 55-65% | G11: Media · protocolo serie | H11: Latente / nicho
A13: 2. PANORAMA DE PAUTA — BOGOTÁ / COLOMBIA (referencia 2025-2026)
A14: Plataforma | B14: CPM típico (COP) | C14: CPC típico (COP) | D14: Costo x lead estimado (COP) | E14: Intención usuario | F14: Mejor rol en el funnel | G14: Presup. mín. útil / mes | H14: Nota
A15: Google Ads (búsqueda) | B15: — | C15: 800 - 3.500 | D15: 50.000 - 150.000 | E15: Alta (captura) | F15: Capturar demanda que YA existe: 'precio botox bogotá', 'relleno labios precio' | G15: $300k - $500k | H15: CVR salud ~8%. Clic caro pero convierte.
A16: Meta (IG/FB) | B16: 6.000 - 15.000 | C16: 250 - 1.500 | D16: 8.000 - 25.000 | E16: Media (interrumpe) | F16: Generar demanda + retargeting + antes/después. Audiencia 30+ | G16: $600k | H16: CPM subiendo 18-25% interanual.
A17: TikTok | B17: 1.500 - 4.000 | C17: 200 - 1.200 | D17: Variable (frío) | E17: Baja (entretenim.) | F17: Top-funnel / marca / prejuvenation. Audiencia <35, video nativo | G17: $1.5M | H17: CPM 30-40% < Meta pero exige video constante.

Sheet Matriz Scoring
A1: MATRIZ DE SCORING DE PRODUCTO Y PRIORIZACIÓN
Q2: Σ pesos (=100%)
A3: PESOS | H3: 0.15 | I3: 0.2 | J3: 0.12 | K3: 0.1 | L3: 0.11 | M3: 0.13 | N3: 0.08 | O3: 0.05 | P3: 0.06 | Q3: =SUM(H3:P3) -> 1
A4: Servicio | B4: Ticket prom. (COP) | C4: Margen bruto % | D4: Utilidad bruta /sesión (COP) | E4: Compras esperadas 24m | F4: LTV bruto 24m (COP) | G4: Ciclo cierre (días) | H4: Demanda / intención | I4: Eficiencia captación (LTV:CAC · link) | J4: Ticket promedio | K4: Margen bruto | L4: Recurrencia / frecuencia | M4: LTV (24m) | N4: Ciclo cierre (corto=mejor) | O4: Throughput / capacidad | P4: Baja necesidad educación | Q4: Puntaje ponderado | R4: Rank
A5: Toxina botulínica (botox) | B5: 1100000 | C5: 0.72 | D5: =B5*C5 -> 792000 | E5: 5 | F5: =D5*E5 -> 3960000 | G5: 7 | H5: 5 | I5: ='Pauta x Producto'!Q6 -> 5 | J5: 3 | K5: 4 | L5: 5 | M5: 5 | N5: 5 | O5: 4 | P5: 5 | Q5: =SUMPRODUCT(H5:P5,$H$3:$P$3) -> 4.61 | R5: =RANK(Q5,$Q$5:$Q$11) -> 1
A6: Ác. hialurónico — volumen (labios/armonización) | B6: 1400000 | C6: 0.68 | D6: =B6*C6 -> 952000 | E6: 2 | F6: =D6*E6 -> 1904000 | G6: 10 | H6: 5 | I6: ='Pauta x Producto'!Q7 -> 4 | J6: 4 | K6: 4 | L6: 3 | M6: 4 | N6: 4 | O6: 3 | P6: 4 | Q6: =SUMPRODUCT(H6:P6,$H$3:$P$3) -> 3.99 | R6: =RANK(Q6,$Q$5:$Q$11) -> 3
A7: Ác. hialurónico — hidratación (skinboosters/NCTF) | B7: 1150000 | C7: 0.62 | D7: =B7*C7 -> 713000 | E7: 4 | F7: =D7*E7 -> 2852000 | G7: 7 | H7: 4 | I7: ='Pauta x Producto'!Q8 -> 4 | J7: 3 | K7: 3 | L7: 4 | M7: 4 | N7: 4 | O7: 4 | P7: 3 | Q7: =SUMPRODUCT(H7:P7,$H$3:$P$3) -> 3.72 | R7: =RANK(Q7,$Q$5:$Q$11) -> 5
A8: Microagujas (+ exosomas / NCTF) | B8: 750000 | C8: 0.7 | D8: =B8*C8 -> 525000 | E8: 5 | F8: =D8*E8 -> 2625000 | G8: 5 | H8: 4 | I8: ='Pauta x Producto'!Q9 -> 5 | J8: 2 | K8: 4 | L8: 5 | M8: 3 | N8: 5 | O8: 4 | P8: 4 | Q8: =SUMPRODUCT(H8:P8,$H$3:$P$3) -> 4.02 | R8: =RANK(Q8,$Q$5:$Q$11) -> 2
A9: Peelings químicos | B9: 400000 | C9: 0.8 | D9: =B9*C9 -> 320000 | E9: 5 | F9: =D9*E9 -> 1600000 | G9: 3 | H9: 4 | I9: ='Pauta x Producto'!Q10 -> 5 | J9: 1 | K9: 5 | L9: 5 | M9: 2 | N9: 5 | O9: 5 | P9: 5 | Q9: =SUMPRODUCT(H9:P9,$H$3:$P$3) -> 3.98 | R9: =RANK(Q9,$Q$5:$Q$11) -> 4
A10: Bioestimuladores (Sculptra/Radiesse/Profhilo) | B10: 2600000 | C10: 0.58 | D10: =B10*C10 -> 1508000 | E10: 2 | F10: =D10*E10 -> 3016000 | G10: 21 | H10: 3 | I10: ='Pauta x Producto'!Q11 -> 2 | J10: 5 | K10: 3 | L10: 2 | M10: 4 | N10: 2 | O10: 2 | P10: 2 | Q10: =SUMPRODUCT(H10:P10,$H$3:$P$3) -> 2.87 | R10: =RANK(Q10,$Q$5:$Q$11) -> 6
A11: Enzimas recombinantes (corporal) | B11: 900000 | C11: 0.6 | D11: =B11*C11 -> 540000 | E11: 4 | F11: =D11*E11 -> 2160000 | G11: 14 | H11: 2 | I11: ='Pauta x Producto'!Q12 -> 2 | J11: 3 | K11: 3 | L11: 4 | M11: 3 | N11: 3 | O11: 3 | P11: 2 | Q11: =SUMPRODUCT(H11:P11,$H$3:$P$3) -> 2.7 | R11: =RANK(Q11,$Q$5:$Q$11) -> 7

Sheet Pauta x Producto
A1: ESTUDIO DE PAUTA POR PRODUCTO — COSTO DE ADQUISICIÓN (CAC) · 3 ORILLAS
A3: Presupuesto mensual de pauta (COP): | D3: 2500000 | E3: ← edítalo (escenario ppto reducido)
A5: Servicio | B5: Estrategia | C5: Volumen búsqueda | D5: Canal principal | E5: CPC est. (COP) | F5: Conv. landing→lead | G5: CPL est. (COP) | H5: Cierre lead→pac. | I5: CAC est. (COP) | J5: Ticket (COP) | K5: Util. bruta /sesión | L5: LTV bruto 24m | M5: CAC % ticket | N5: LTV : CAC | O5: Payback (sesiones) | P5: Pacientes/ mes (ppto) | Q5: Eficiencia (1-5)
A6: Toxina botulínica (botox) | B6: Captura | C6: Alto | D6: Google + Meta RT | E6: 2000 | F6: 0.11 | G6: =E6/F6 -> 18181.818 | H6: 0.35 | I6: =G6/H6 -> 51948.052 | J6: ='Matriz Scoring'!B5 -> 1100000 | K6: ='Matriz Scoring'!D5 -> 792000 | L6: ='Matriz Scoring'!F5 -> 3960000 | M6: =I6/J6 -> 0.047225502 | N6: =L6/I6 -> 76.23 | O6: =I6/K6 -> 0.065590975 | P6: =$D$3/I6 -> 48.125 | Q6: =IF(N6>=50,5,IF(N6>=25,4,IF(N6>=12,3,IF(N6>=6,2,1)))) -> 5
A7: Ác. hialurónico — volumen (labios/armonización) | B7: Captura | C7: Alto | D7: Google + Meta | E7: 2500 | F7: 0.11 | G7: =E7/F7 -> 22727.273 | H7: 0.35 | I7: =G7/H7 -> 64935.065 | J7: ='Matriz Scoring'!B6 -> 1400000 | K7: ='Matriz Scoring'!D6 -> 952000 | L7: ='Matriz Scoring'!F6 -> 1904000 | M7: =I7/J7 -> 0.046382189 | N7: =L7/I7 -> 29.3216 | O7: =I7/K7 -> 0.068209102 | P7: =$D$3/I7 -> 38.5 | Q7: =IF(N7>=50,5,IF(N7>=25,4,IF(N7>=12,3,IF(N7>=6,2,1)))) -> 4
A8: Ác. hialurónico — hidratación (skinboosters/NCTF) | B8: Mixta | C8: Medio | D8: Meta + Google | E8: 1500 | F8: 0.09 | G8: =E8/F8 -> 16666.667 | H8: 0.25 | I8: =G8/H8 -> 66666.667 | J8: ='Matriz Scoring'!B7 -> 1150000 | K8: ='Matriz Scoring'!D7 -> 713000 | L8: ='Matriz Scoring'!F7 -> 2852000 | M8: =I8/J8 -> 0.057971014 | N8: =L8/I8 -> 42.78 | O8: =I8/K8 -> 0.093501636 | P8: =$D$3/I8 -> 37.5 | Q8: =IF(N8>=50,5,IF(N8>=25,4,IF(N8>=12,3,IF(N8>=6,2,1)))) -> 4
A9: Microagujas (+ exosomas / NCTF) | B9: Mixta | C9: Medio | D9: Meta + Google | E9: 1200 | F9: 0.1 | G9: =E9/F9 -> 12000 | H9: 0.28 | I9: =G9/H9 -> 42857.143 | J9: ='Matriz Scoring'!B8 -> 750000 | K9: ='Matriz Scoring'!D8 -> 525000 | L9: ='Matriz Scoring'!F8 -> 2625000 | M9: =I9/J9 -> 0.057142857 | N9: =L9/I9 -> 61.25 | O9: =I9/K9 -> 0.081632653 | P9: =$D$3/I9 -> 58.333333 | Q9: =IF(N9>=50,5,IF(N9>=25,4,IF(N9>=12,3,IF(N9>=6,2,1)))) -> 5
A10: Peelings químicos | B10: Mixta | C10: Medio | D10: Meta + Google | E10: 900 | F10: 0.11 | G10: =E10/F10 -> 8181.8182 | H10: 0.3 | I10: =G10/H10 -> 27272.727 | J10: ='Matriz Scoring'!B9 -> 400000 | K10: ='Matriz Scoring'!D9 -> 320000 | L10: ='Matriz Scoring'!F9 -> 1600000 | M10: =I10/J10 -> 0.068181818 | N10: =L10/I10 -> 58.666667 | O10: =I10/K10 -> 0.085227273 | P10: =$D$3/I10 -> 91.666667 | Q10: =IF(N10>=50,5,IF(N10>=25,4,IF(N10>=12,3,IF(N10>=6,2,1)))) -> 5
A11: Bioestimuladores (Sculptra/Radiesse/Profhilo) | B11: Generación | C11: Bajo | D11: Meta contenido + RT | E11: 2200 | F11: 0.07 | G11: =E11/F11 -> 31428.571 | H11: 0.12 | I11: =G11/H11 -> 261904.76 | J11: ='Matriz Scoring'!B10 -> 2600000 | K11: ='Matriz Scoring'!D10 -> 1508000 | L11: ='Matriz Scoring'!F10 -> 3016000 | M11: =I11/J11 -> 0.1007326 | N11: =L11/I11 -> 11.515636 | O11: =I11/K11 -> 0.1736769 | P11: =$D$3/I11 -> 9.5454545 | Q11: =IF(N11>=50,5,IF(N11>=25,4,IF(N11>=12,3,IF(N11>=6,2,1)))) -> 2
A12: Enzimas recombinantes (corporal) | B12: Generación | C12: Bajo | D12: Meta + TikTok | E12: 1800 | F12: 0.06 | G12: =E12/F12 -> 30000 | H12: 0.1 | I12: =G12/H12 -> 300000 | J12: ='Matriz Scoring'!B11 -> 900000 | K12: ='Matriz Scoring'!D11 -> 540000 | L12: ='Matriz Scoring'!F11 -> 2160000 | M12: =I12/J12 -> 0.33333333 | N12: =L12/I12 -> 7.2 | O12: =I12/K12 -> 0.55555556 | P12: =$D$3/I12 -> 8.3333333 | Q12: =IF(N12>=50,5,IF(N12>=25,4,IF(N12>=12,3,IF(N12>=6,2,1)))) -> 2
A13: Bioestimuladores — vía MARCA (Radiesse/Sculptra) · ESCENARIO | B13: Captura | C13: Medio | D13: Google marca + Meta | E13: 2000 | F13: 0.09 | G13: =E13/F13 -> 22222.222 | H13: 0.22 | I13: =G13/H13 -> 101010.1 | J13: ='Matriz Scoring'!B10 -> 2600000 | K13: ='Matriz Scoring'!D10 -> 1508000 | L13: ='Matriz Scoring'!F10 -> 3016000 | M13: =I13/J13 -> 0.038850039 | N13: =L13/I13 -> 29.8584 | O13: =I13/K13 -> 0.066982826 | P13: =$D$3/I13 -> 24.75 | Q13: =IF(N13>=50,5,IF(N13>=25,4,IF(N13>=12,3,IF(N13>=6,2,1)))) -> 4

Sheet Términos de Búsqueda
A1: TÉRMINOS DE BÚSQUEDA
A3: Servicio | B3: Término de búsqueda | C3: Búsquedas/mes (real) | D3: Competencia | E3: CPC puja tope (COP, bajo-alto) | F3: Intención / nota
A4: Botox | B4: botox | C4: 5000 | D4: Baja | E4: $1,000 - $1,500 | F4: Cabeza de categoría, intención de tratamiento, competencia BAJA ★
A5: Botox | B5: toxina botulínica | C5: 500 | D5: Baja | E5: $967 - $3,811
A6: Botox | B6: botox precio | C6: 500 | D6: Baja | E6: —
A7: Botox | B7: toxina botulínica precio | C7: 500 | D7: Baja | E7: $709 - $1,906
A8: Botox | B8: botox para cara | C8: 500 | D8: Baja | E8: —
A9: Botox | B9: botox precio bogotá | C9: 50 | D9: Baja | E9: — | F9: Pocos escriben 'bogotá' explícito
A10: Botox | B10: cuánto cuesta el botox | C10: 50 | D10: Baja | E10: —
A11: Ác. hial. volumen | B11: ácido hialurónico | C11: 5000 | D11: Alta | E11: $521 - $2,196 | F11: CONTAMINADO: mayormente CREMAS (Vichy, L'Oréal, The Ordinary)
A12: Ác. hial. volumen | B12: para que sirve el ácido hialurónico | C12: 5000 | D12: Baja | E12: $215 - $721 | F12: Informacional, no compra
A13: Ác. hial. volumen | B13: ácido hialurónico precio | C13: 500 | D13: Alta | E13: $578 - $1,503
A14: Ác. hial. volumen | B14: ácido hialurónico inyectable | C14: 500 | D14: Media | E14: $677 - $2,209 | F14: Intención de tratamiento real
A15: Ác. hial. volumen | B15: armonización facial | C15: 500 | D15: Media | E15: $642 - $1,832 | F15: ↑900% interanual: la tendencia que sube
A16: Ác. hial. volumen | B16: relleno de labios | C16: 50 | D16: Media | E16: $1,127 - $3,818 | F16: Volumen bajo, CPC alto
A17: Ác. hial. volumen | B17: aumento de labios | C17: 50 | D17: Media | E17: $1,279 - $3,482
A18: Ác. hial. volumen | B18: relleno de ojeras | C18: 50 | D18: Media | E18: $1,965 - $5,790 | F18: CPC más alto del estudio (clic muy valioso)
A19: Ác. hial. volumen | B19: ácido hialurónico labios | C19: 50 | D19: Media | E19: $839 - $2,674
A20: Bioestimuladores | B20: radiesse | C20: 5000 | D20: Baja | E20: $605 - $1,629 | F20: Demanda de marca alta + competencia BAJA
A21: Bioestimuladores | B21: sculptra | C21: 5000 | D21: Baja | E21: $811 - $3,286 | F21: Igual que Radiesse: gran oportunidad de captura
A22: Bioestimuladores | B22: bioestimuladores | C22: 500 | D22: Baja | E22: $642 - $1,843
A23: Bioestimuladores | B23: radiesse precio | C23: 500 | D23: Media | E23: $696 - $1,883
A24: Bioestimuladores | B24: sculptra precio | C24: 500 | D24: Baja | E24: —
A25: Bioestimuladores | B25: profhilo | C25: 500 | D25: Baja | E25: $686 - $2,362
A26: Bioestimuladores | B26: harmonyca | C26: 500 | D26: Baja | E26: $702 - $2,921
A27: Bioestimuladores | B27: juvelook | C27: 500 | D27: Baja | E27: $739 - $2,074 | F27: 900%: marca nueva creciendo
A28: Hidratación / NCTF | B28: nctf | C28: 500 | D28: Baja | E28: $902 - $2,494
A29: Hidratación / NCTF | B29: nctf 135 | C29: 500 | D29: Baja | E29: $810 - $1,335
A30: Hidratación / NCTF | B30: nctf ojeras | C30: 500 | D30: Media | E30: $761 - $2,211
A31: Hidratación / NCTF | B31: rejuvenecimiento facial | C31: 500 | D31: Media | E31: $834 - $2,178 | F31: Amplio, poca intención específica
A32: Hidratación / NCTF | B32: hidratación facial profunda | C32: 50 | D32: Media | E32: $880 - $2,836
A33: Hidratación / NCTF | B33: mesoterapia facial | C33: 50 | D33: Media | E33: $818 - $1,963
A34: Microagujas | B34: dermapen | C34: 5000 | D34: Alta | E34: $202 - $1,792 | F34: COMPRADORES del aparato, no del tratamiento
A35: Microagujas | B35: microneedling | C35: 500 | D35: Alta | E35: $825 - $3,353 | F35: Intención de tratamiento real
A36: Microagujas | B36: dermapen facial | C36: 500 | D36: Alta | E36: $468 - $1,329
A37: Microagujas | B37: dermapen precio | C37: 500 | D37: Alta | E37: $79 - $1,010
A38: Microagujas | B38: microagujas | C38: 50 | D38: Alta | E38: —
A39: Peelings | B39: peeling facial | C39: 500 | D39: Alta | E39: $694 - $2,546
A40: Peelings | B40: microdermoabrasión | C40: 500 | D40: Alta | E40: $678 - $3,614
A41: Peelings | B41: peeling ultrasónico | C41: 500 | D41: Alta | E41: —
...

Sheet Árbol de Producto
A1: ÁRBOL DE PRODUCTO
A3: Nivel | B3: Servicio(s) | C3: Rol estratégico | D3: Ticket / LTV | E3: Canal de pauta principal
A4: 0. ENTRADA | B4: Valoración inicial | C4: Mecanismo de conversión y confianza. Casi todo entra por aquí. Gratis o con abono al tratamiento. | D4: Bajo / — | E4: Google + Meta (oferta de valoración)
A5: 1. VELOCIDAD Y CAJA | B5: Botox (tercio superior / baby botox) | C5: Motor de caja. Demanda de marca existente, decisión y procedimiento rápidos, alta recurrencia, margen alto. | D5: Medio / ALTO (por recurrencia) | E5: Google (captura) + Meta retargeting
A6: 1. VELOCIDAD Y CAJA | B6: Hidratación (skinboosters/NCTF) · Microagujas · Peelings | C6: Entradas accesibles, bajo riesgo percibido, se venden en paquete (caja anticipada). Amplían base de pacientes. | D6: Bajo-medio / Medio | E6: Meta + TikTok (prejuvenation)
A7: 2. TICKET ALTO QUE VENDE | B7: Ácido hialurónico — volumen (labios, ojeras, armonización) | C7: Alto valor CON demanda de marca real ('relleno labios precio'). Ticket alto y ciclo aún corto. El mejor 'segundo producto'. | D7: Alto / Alto | E7: Google (captura) + Meta antes/después
A8: 3. ALTO VALOR / ASCENSIÓN | B8: Bioestimuladores · Enzimas recombinantes | C8: Máximo ticket y margen absoluto, pero exigen educación, consideración y ciclo largo. Se venden al paciente que ya confía. | D8: Muy alto / Alto | E8: Contenido + remarketing a pacientes existentes
A10: SEGMENTOS GANADORES A ATACAR PRIMERO:
A11: Avatar 1 — 'La Preventiva' (26-38) | B11: Entra por botox preventivo + hidratación/microagujas. Captura la tendencia prejuvenation (el segmento de mayor crecimiento). Alta recurrencia, bajo riesgo percibido.
A12: Avatar 2 — 'La Armonización Natural' (30-45) | B12: Entra por ácido hialurónico de volumen (labios/ojeras) + botox. Demanda de marca transaccional, ticket más alto. Asciende a bioestimuladores.
